Workbook
Name ___INDEX_SHEET___ASAP_Utilities: 'Index sheet'!$A$1
Name __aaa2: COLUMN()
Name __DATE1: "TRIGGER.MSFOR|203|501"
Name __Dumpster: 0
Name _DCFLastMonth: OFFSET('P&Ls_Consolidated_OLD'!_DCFFirstMonth,0,#REF!*12-1)
Name _RLATools_Live: 0
Name _RLATools_PortfolioRefresh: 0
Name _VALIDATE_NOICAP: OFFSET(#REF!,1,0,#REF!,1)
Name _VALIDATE_NOIEXIT: OFFSET(#REF!,1,0,#REF!,1)
Name aaaCol: COLUMN()
Name aaaRow: ROW()
Name ACC: "$Original.$A$#REF!"
Name Actual_Being_Paid_Series: OFFSET(#REF!,0,0,#REF!,1)
Name AddALinePartnerships: 'Sales & Percentage Rent'!AddALinePartnerships
Name Admin_no: 1
Name ALC_DRILL_1: "GL Transactions by Account Drill 2-0 (SP60 - SQL)||SP60-SQL-XL02-2-0||ACCOUNTNO;XLGENIE_CURRENT_PERIOD;SelectedYear;CompanyNo||IS - Actual Budget Prior - IFRS||1"
Name ALCHEMEX_DRILL_SET: "GL_001"
Name AllProjPages: #REF!,#REF!,#REF!,#REF!
Name amort.ExpCount: ROW(INDEX(#REF!,MATCH(9.99999999999999E+307,#REF!)))
Name amort.Table: #REF!:INDEX(#REF!,MATCH(9.99999999999999E+307,#REF!)+7)
Name Amounts_in: "1000"
Name Annual_Budget_Interest_Expense: SUM(#REF!)
Name Annual_Budget_Total_Amort_Recov_Capital: SUM(#REF!)
Name Annual_Budget_Total_Taxes: SUM(#REF!)
Name ARCPUBURL: ""
Name BacktoPartnership: 'Sales & Percentage Rent'!BacktoPartnership
Name BLDG.__410: "CAMSCH"
Name BonusNames: #REF!,#REF!
Name BPAGE: "1"
Name BUDGET_utili_REAIS: #REF!,#REF!,#REF!,#REF!
Name BUDGET_WORKSHEET___REAIS: #REF!,#REF!,#REF!,#REF!,#REF!
Name BUDGET_WORKSHEET_US: #REF!,#REF!,#REF!,#REF!,#REF!
Name Bugget_w: #REF!,#REF!,#REF!,#REF!,#REF!
Name Building: "One University Avenue"
Name Button_1: "CalifornianCasa_UnitDetails_List"
Name Button_80: "The_Bonavista_UnitDetails_List"
Name CellContents: _xlfn.FORMULATEXT(INDIRECT(ADDRESS(ROW(), COLUMN())))
Name Choices_Wrapper: Proforma!Choices_Wrapper
Name Choices_Wrapper5: Proforma!Choices_Wrapper5
Name CI: "HEAD"
Name COL1STYR: 7
Name Company_name: "SLOV - KAUFRING"
Name Contract_NRI_Series: OFFSET(#REF!,0,0,#REF!,1)
Name Corporate_tax_rate: 0.4
Name CPAGE: "37"
Name CPNMB: "1"
Name cSum: 9
Name CTIM2: "122917"
Name Current_Forecast_Series: OFFSET(#REF!,0,0,#REF!,1)
Name DataDisplayed: "user"
Name Date_Series: OFFSET(#REF!,0,0,#REF!,1)
Name DeleteAccumAmort: #REF!,#REF!
Name DeleteFA: #REF!,#REF!,#REF!
Name DeleteIntangibleAssets: #REF!,#REF!
Name DeleteLand: #REF!,#REF!
Name DeleteTaxRollforward: #REF!,#REF!,#REF!,#REF!,#REF!,#REF!
Name DelLevClear: #REF!,#REF!,#REF!,#REF!,#REF!,#REF!,#REF!
Name delLevClearExec: #REF!,#REF!
Name devsummprint: #REF!,#REF!+#REF!,#REF!,#REF!
Name DVNAM: "XF175E"

Sheet Index sheet
A1: Sheet index:
A2: Title Page
A3: DD Req List
A4: UW Notes
A5: UW-->
A6: Pres Summ
A7: Exec Summ
A8: Return Metrics
A9: Exhibits-->
A10: Global
A11: Proforma
A12: P&Ls_Con
... A48: COA

Sheet CAM Assumptions
B2: Misc Notes & Questions:
B3: - Assumed all tenants roll to options and recoveries continue prior
B4: - Assumed Ross continues paying % rent in lieu of actual rent & recoveries throughout option period
B5: - Assumed GSA expenses were not included in historicals, as in SIG OM
B6: - G&A shows up in CAM recs but not in P&Ls
B7: - Mgmt fee show up in CAM recs but not in P&Ls
B8: - Which tax parcels are included in the common area? Do you happen to have the annual tax values for Chipotle and Building T?
B9: - Where are the vacant units that don't appear on stie plan?
B10: Why are the taxes for Boulder Tap House are showing $38,038 actual taxes , while the P&L only reflects approximately $5K in tax expense
B12: Tenant | C12: CAM Recs | D12: Notes / Comments
B13: Chipotle | D13: No CAM Recs, used $22PSF estimated recoveries from Lease Agreement as placeholder
B14: Burlington | C14: Yes
B15: Petsmart | C15: Yes
B16: Boulder Tap | C16: Yes | D16: Line item "General Administrative/Office" in the CAM Recs cannot be found on the 2025 Expenses. Modeled as reference only expenses line item in Argus for the meantime
B17: Ulta | D17: No CAM Recs, used $6.10PSF estimated recoveries from Lease Agreement as placeholder
B18: Five Below | D18: No CAM Recs, used $6.10PSF estimated recoveries from Lease Agreement as placeholder
B19: Bath and Body | D19: No CAM Recs, used $6.10PSF estimated recoveries from Lease Agreement as placeholder
B20: Maurice's | D20: No CAM Recs, used $6.10PSF estimated recoveries from Lease Agreement as placeholder
B21: Ross* | C21: n/a | D21: In percentage rent, no CAM Recs needed
B22: Michael's | C22: Yes | D22: Line item "General Administrative/Office" in the CAM Recs cannot be found on the 2025 Expenses. Modeled as reference only expenses line item in Argus for the meantime
B23: GSA | C23: n/a | D23: Gross
B24: JCPenney | C24: n/a | D24: Full Service
B26: NAP Tenants
B27: U-Haul | C27: Yes | D27: Line item "General Administrative/Office" in the CAM Recs cannot be found on the 2025 Expenses. Modeled as reference only expenses line item in Argus for the meantime
B28: Christian Brothers | C28: Yes | D28: Line item "General Administrative/Office" in the CAM Recs cannot be found on the 2025 Expenses. Modeled as reference only expenses line item in Argus for the meantime
B29: Westdale Residential Housing CAM | D29: No CAM Recs, used 2025+3% amount from 2025 WCRV#1 Revenue Summary
B30: Ironside Apparel | D30: No CAM Recs, used 2025+3% amount from 2025 WCRV#1 Revenue Summary
B31: Mandarin Spice | D31: No CAM Recs, used 2025+3% amount from 2025 WCRV#1 Revenue Summary
B32: Home2 | C32: Yes | D32: Line item "General Administrative/Office" in the CAM Recs cannot be found on the 2025 Expenses. Modeled as reference only expenses line item in Argus for the meantime
B33: First Federal Credit Union CAM | C33: Yes | D33: Line item "General Administrative/Office" in the CAM Recs cannot be found on the 2025 Expenses. Modeled as reference only expenses line item in Argus for the meantime
B34: Westdale Hotel Associates CAM | D34: No CAM Recs, used 2025+3% amount from 2025 WCRV#1 Revenue Summary
B35: Edgewood Station CAM | C35: Yes | D35: Line item "General Administrative/Office" in the CAM Recs cannot be found on the 2025 Expenses. Modeled as reference only expenses line item in Argus for the meantime
B36: US Bank CAM | C36: Yes | D36: Line item "General Administrative/Office" in the CAM Recs cannot be found on the 2025 Expenses. Modeled as reference only expenses line item in Argus for the meantime
B37: Take5 | C37: Yes | D37: Line item "General Administrative/Office" in the CAM Recs cannot be found on the 2025 Expenses. Modeled as reference only expenses line item in Argus for the meantime
B38: 7 Brew/Sugarfire | D38: No CAM Recs, used 2025+3% amount from 2025 WCRV#1 Revenue Summary
B39: Lamb Land- Lot 2 CAM (Noodles) | D39: No CAM Recs, used 2025+3% amount from 2025 WCRV#1 Revenue Summary
B40: RNR Tire (formerly EP 3-4 CAM (Old Chicago)) | D40: No CAM Recs, used 2025+3% amount from 2025 WCRV#1 Revenue Summary
B41: Slow, LLC - Lot 5 CAM (Freddy's) | D41: No CAM Recs, used 2025+3% amount from 2025 WCRV#1 Revenue Summary
B42: Mr. Car Wash - Lot P | D42: No CAM Recs, used 2025+3% amount from 2025 WCRV#1 Revenue Summary
B43: EP - Lot 7 CAM (CFA) | D43: No CAM Recs, used 2025+3% amount from 2025 WCRV#1 Revenue Summary
...

Sheet RR Assumptions
C3: ASSUMPTIONS | X3: =Global!$G$7 | Z3: ='Rent Roll-Detailed'!$H$65
D4: **Note: This is a summary of the general assumptions, rent roll, and MLA tabs combined to make it easier to provide feedback. If you make any updates, please change the highlight color so we can identify what changed.**
C5: GENERAL | J5: MARKET LEASING ASSUMPTIONS
D6: General Growth Rate: | E6: =Global!G28 | K6: Market Rent | R6: Free Rent | T6: Tenant Improvement | V6: Leasing Commission
D7: Market Growth Rate: | E7: =Global!G32 | J7: Assigned Name | K7: New | L7: Renew | M7: Escalation | N7: Reimbursement | O7: Lease Term | P7: Renewal Prob. | Q7: Downtime | R7: New | S7: Renew | T7: New | U7: Renew | V7: New | W7: Renew
D8: Expense Growth Rate: | E8: =Global!G29 | J8: $22.00 PSF NNN | K8: =INDEX(MLAs!$E$8:$N$8,MATCH('RR Assumptions'!$J8,MLAs!$E$5:$N$5,0)) | L8: =INDEX(MLAs!$E$9:$N$9,MATCH('RR Assumptions'!$J8,MLAs!$E$5:$N$5,0)) | M8: =INDEX(MLAs!$E$10:$N$10,MATCH('RR Assumptions'!$J8,MLAs!$E$5:$N$5,0)) | N8: =INDEX(MLAs!$E$13:$N$13,MATCH('RR Assumptions'!$J8,MLAs!$E$5:$N$5,0)) | O8: =INDEX(MLAs!$E$14:$N$14,MATCH('RR Assumptions'!$J8,MLAs!$E$5:$N$5,0)) | P8: =INDEX(MLAs!$E$15:$N$15,MATCH('RR Assumptions'!$J8,MLAs!$E$5:$N$5,0)) | Q8: =INDEX(MLAs!$E$16:$N$16,MATCH('RR Assumptions'!$J8,MLAs!$E$5:$N$5,0)) | R8: =INDEX(MLAs!$E$19:$N$19,MATCH('RR Assumptions'!$J8,MLAs!$E$5:$N$5,0)) | S8: =INDEX(MLAs!$E$20:$N$20,MATCH('RR Assumptions'!$J8,MLAs!$E$5:$N$5,0)) | T8: =INDEX(MLAs!$E$24:$N$24,MATCH('RR Assumptions'!$J8,MLAs!$E$5:$N$5,0)) | U8: =INDEX(MLAs!$E$25:$N$25,MATCH('RR Assumptions'!$J8,MLAs!$E$5:$N$5,0)) | V8: =INDEX(MLAs!$E$29:$N$29,MATCH('RR Assumptions'!$J8,MLAs!$E$5:$N$5,0)) | W8: =INDEX(MLAs!$E$30:$N$30,MATCH('RR Assumptions'!$J8,MLAs!$E$5:$N$5,0))
D9: Vacancy: | E9: =Global!G22 | J9: $27.00 PSF NNN | K9: =INDEX(MLAs!$E$8:$N$8,MATCH('RR Assumptions'!$J9,MLAs!$E$5:$N$5,0)) | L9: =INDEX(MLAs!$E$9:$N$9,MATCH('RR Assumptions'!$J9,MLAs!$E$5:$N$5,0)) | M9: =INDEX(MLAs!$E$10:$N$10,MATCH('RR Assumptions'!$J9,MLAs!$E$5:$N$5,0)) | N9: =INDEX(MLAs!$E$13:$N$13,MATCH('RR Assumptions'!$J9,MLAs!$E$5:$N$5,0)) | O9: =INDEX(MLAs!$E$14:$N$14,MATCH('RR Assumptions'!$J9,MLAs!$E$5:$N$5,0)) | P9: =INDEX(MLAs!$E$15:$N$15,MATCH('RR Assumptions'!$J9,MLAs!$E$5:$N$5,0)) | Q9: =INDEX(MLAs!$E$16:$N$16,MATCH('RR Assumptions'!$J9,MLAs!$E$5:$N$5,0)) | R9: =INDEX(MLAs!$E$19:$N$19,MATCH('RR Assumptions'!$J9,MLAs!$E$5:$N$5,0)) | S9: =INDEX(MLAs!$E$20:$N$20,MATCH('RR Assumptions'!$J9,MLAs!$E$5:$N$5,0)) | T9: =INDEX(MLAs!$E$24:$N$24,MATCH('RR Assumptions'!$J9,MLAs!$E$5:$N$5,0)) | U9: =INDEX(MLAs!$E$25:$N$25,MATCH('RR Assumptions'!$J9,MLAs!$E$5:$N$5,0)) | V9: =INDEX(MLAs!$E$29:$N$29,MATCH('RR Assumptions'!$J9,MLAs!$E$5:$N$5,0)) | W9: =INDEX(MLAs!$E$30:$N$30,MATCH('RR Assumptions'!$J9,MLAs!$E$5:$N$5,0))
D10: Excluded Tenants: | E10: Yes | F10: if "Yes" please indicate in the provided RR below | J10: $30.00 PSF NNN | K10: =INDEX(MLAs!$E$8:$N$8,MATCH('RR Assumptions'!$J10,MLAs!$E$5:$N$5,0)) | L10: =INDEX(MLAs!$E$9:$N$9,MATCH('RR Assumptions'!$J10,MLAs!$E$5:$N$5,0)) | M10: =INDEX(MLAs!$E$10:$N$10,MATCH('RR Assumptions'!$J10,MLAs!$E$5:$N$5,0)) | N10: =INDEX(MLAs!$E$13:$N$13,MATCH('RR Assumptions'!$J10,MLAs!$E$5:$N$5,0)) | O10: =INDEX(MLAs!$E$14:$N$14,MATCH('RR Assumptions'!$J10,MLAs!$E$5:$N$5,0)) | P10: =INDEX(MLAs!$E$15:$N$15,MATCH('RR Assumptions'!$J10,MLAs!$E$5:$N$5,0)) | Q10: =INDEX(MLAs!$E$16:$N$16,MATCH('RR Assumptions'!$J10,MLAs!$E$5:$N$5,0)) | R10: =INDEX(MLAs!$E$19:$N$19,MATCH('RR Assumptions'!$J10,MLAs!$E$5:$N$5,0)) | S10: =INDEX(MLAs!$E$20:$N$20,MATCH('RR Assumptions'!$J10,MLAs!$E$5:$N$5,0)) | T10: =INDEX(MLAs!$E$24:$N$24,MATCH('RR Assumptions'!$J10,MLAs!$E$5:$N$5,0)) | U10: =INDEX(MLAs!$E$25:$N$25,MATCH('RR Assumptions'!$J10,MLAs!$E$5:$N$5,0)) | V10: =INDEX(MLAs!$E$29:$N$29,MATCH('RR Assumptions'!$J10,MLAs!$E$5:$N$5,0)) | W10: =INDEX(MLAs!$E$30:$N$30,MATCH('RR Assumptions'!$J10,MLAs!$E$5:$N$5,0))
J11: $27.00 PSF NNN | K11: =INDEX(MLAs!$E$8:$N$8,MATCH('RR Assumptions'!$J11,MLAs!$E$5:$N$5,0)) | L11: =INDEX(MLAs!$E$9:$N$9,MATCH('RR Assumptions'!$J11,MLAs!$E$5:$N$5,0)) | M11: =INDEX(MLAs!$E$10:$N$10,MATCH('RR Assumptions'!$J11,MLAs!$E$5:$N$5,0)) | N11: =INDEX(MLAs!$E$13:$N$13,MATCH('RR Assumptions'!$J11,MLAs!$E$5:$N$5,0)) | O11: =INDEX(MLAs!$E$14:$N$14,MATCH('RR Assumptions'!$J11,MLAs!$E$5:$N$5,0)) | P11: =INDEX(MLAs!$E$15:$N$15,MATCH('RR Assumptions'!$J11,MLAs!$E$5:$N$5,0)) | Q11: =INDEX(MLAs!$E$16:$N$16,MATCH('RR Assumptions'!$J11,MLAs!$E$5:$N$5,0)) | R11: =INDEX(MLAs!$E$19:$N$19,MATCH('RR Assumptions'!$J11,MLAs!$E$5:$N$5,0)) | S11: =INDEX(MLAs!$E$20:$N$20,MATCH('RR Assumptions'!$J11,MLAs!$E$5:$N$5,0)) | T11: =INDEX(MLAs!$E$24:$N$24,MATCH('RR Assumptions'!$J11,MLAs!$E$5:$N$5,0)) | U11: =INDEX(MLAs!$E$25:$N$25,MATCH('RR Assumptions'!$J11,MLAs!$E$5:$N$5,0)) | V11: =INDEX(MLAs!$E$29:$N$29,MATCH('RR Assumptions'!$J11,MLAs!$E$5:$N$5,0)) | W11: =INDEX(MLAs!$E$30:$N$30,MATCH('RR Assumptions'!$J11,MLAs!$E$5:$N$5,0))
J12: Retail D - ATM $3,333/ mo | K12: =INDEX(MLAs!$E$8:$N$8,MATCH('RR Assumptions'!$J12,MLAs!$E$5:$N$5,0)) | L12: =INDEX(MLAs!$E$9:$N$9,MATCH('RR Assumptions'!$J12,MLAs!$E$5:$N$5,0)) | M12: =INDEX(MLAs!$E$10:$N$10,MATCH('RR Assumptions'!$J12,MLAs!$E$5:$N$5,0)) | N12: =INDEX(MLAs!$E$13:$N$13,MATCH('RR Assumptions'!$J12,MLAs!$E$5:$N$5,0)) | O12: =INDEX(MLAs!$E$14:$N$14,MATCH('RR Assumptions'!$J12,MLAs!$E$5:$N$5,0)) | P12: =INDEX(MLAs!$E$15:$N$15,MATCH('RR Assumptions'!$J12,MLAs!$E$5:$N$5,0)) | Q12: =INDEX(MLAs!$E$16:$N$16,MATCH('RR Assumptions'!$J12,MLAs!$E$5:$N$5,0)) | R12: =INDEX(MLAs!$E$19:$N$19,MATCH('RR Assumptions'!$J12,MLAs!$E$5:$N$5,0)) | S12: =INDEX(MLAs!$E$20:$N$20,MATCH('RR Assumptions'!$J12,MLAs!$E$5:$N$5,0)) | T12: =INDEX(MLAs!$E$24:$N$24,MATCH('RR Assumptions'!$J12,MLAs!$E$5:$N$5,0)) | U12: =INDEX(MLAs!$E$25:$N$25,MATCH('RR Assumptions'!$J12,MLAs!$E$5:$N$5,0)) | V12: =INDEX(MLAs!$E$29:$N$29,MATCH('RR Assumptions'!$J12,MLAs!$E$5:$N$5,0)) | W12: =INDEX(MLAs!$E$30:$N$30,MATCH('RR Assumptions'!$J12,MLAs!$E$5:$N$5,0))
D13: EXPENSES
D14: Mgmt Fee (% of EGR): | E14: =Global!G41
D15: Real Estate Tax: | E15: =Global!G42
D16: Capital Reserve: | E16: =Global!G45
D17: Other Expenses: | E17: =Global!G40 | J17: OTHER ASSUMPTIONS
J18: ='Rent Roll-Detailed'!C69
J19: ='Rent Roll-Detailed'!C70
J20: ='Rent Roll-Detailed'!C71
J21: ='Rent Roll-Detailed'!C72
J22: ='Rent Roll-Detailed'!C75
C23: ONE-LINE RENT ROLL WITH MLA ASSIGNMENT
K24: Market Rent | R24: Free Rent | T24: Tenant Improvement | V24: Leasing Commission
D25: Suite | E25: Tenant | F25: Area (SF) | G25: PRS | H25: Contr. Base Rent PSF | I25: Exclude from Vacancy | J25: MLA Assigned | K25: New | L25: Renew | M25: Escalation | N25: Reimbursement | O25: Lease Term | P25: Renewal Prob. | Q25: Downtime | R25: New | S25: Renew | T25: New | U25: Renew | V25: New | W25: Renew | AB25: ISODD? | AC25: Bldg No
D26: {=_xlfn._xlws.FILTER('Rent Roll-Detailed'!$F$8:$F$60,'Rent Roll-Detailed'!$F$8:$F$60<>"")} | E26: =_xlfn.XLOOKUP($D26,'Rent Roll-Detailed'!$F$8:$F$60,'Rent Roll-Detailed'!$G$8:$G$60) | F26: =_xlfn.XLOOKUP($D26,'Rent Roll-Detailed'!$F$8:$F$60,'Rent Roll-Detailed'!H$8:H$60) | G26: =F26/$F$52 | H26: =IF(E26="Vacant","",_xlfn.XLOOKUP($D26,'Rent Roll-Detailed'!$F$8:$F$60,'Rent Roll-Detailed'!R$8:R$60)) | I26: Yes | J26: =INDEX('One-line RR'!$V$7:$V$12,MATCH('RR Assumptions'!$E26,'One-line RR'!$G$7:$G$12,0)) | K26: =INDEX(K$8:K$20,MATCH($J26,$J$8:$J$20,0)) | L26: =INDEX(L$8:L$23,MATCH($J26,$J$8:$J$23,0)) | M26: =INDEX(M$8:M$23,MATCH($J26,$J$8:$J$23,0)) | N26: =INDEX(N$8:N$23,MATCH($J26,$J$8:$J$23,0)) | O26: =INDEX(O$8:O$23,MATCH($J26,$J$8:$J$23,0)) | P26: =INDEX(P$8:P$23,MATCH($J26,$J$8:$J$23,0)) | Q26: =INDEX(Q$8:Q$23,MATCH($J26,$J$8:$J$23,0)) | R26: =INDEX(R$8:R$23,MATCH($J26,$J$8:$J$23,0)) | S26: =INDEX(S$8:S$23,MATCH($J26,$J$8:$J$23,0)) | ... W26: =INDEX(W$8:W$23,MATCH($J26,$J$8:$J$23,0)) | AB26: =ISODD(MAX(COUNTA($D$26:D26)))
D27: 2 | E27: =_xlfn.XLOOKUP($D27,'Rent Roll-Detailed'!$F$8:$F$60,'Rent Roll-Detailed'!$G$8:$G$60) | F27: =_xlfn.XLOOKUP($D27,'Rent Roll-Detailed'!$F$8:$F$60,'Rent Roll-Detailed'!H$8:H$60) | G27: =F27/$F$52 | H27: =IF(E27="Vacant","",_xlfn.XLOOKUP($D27,'Rent Roll-Detailed'!$F$8:$F$60,'Rent Roll-Detailed'!R$8:R$60)) | I27: Yes | J27: =INDEX('One-line RR'!$V$7:$V$12,MATCH('RR Assumptions'!$E27,'One-line RR'!$G$7:$G$12,0)) | K27: =INDEX(K$8:K$23,MATCH($J27,$J$8:$J$23,0)) | L27: =INDEX(L$8:L$23,MATCH($J27,$J$8:$J$23,0)) | M27: =INDEX(M$8:M$23,MATCH($J27,$J$8:$J$23,0)) | N27: =INDEX(N$8:N$23,MATCH($J27,$J$8:$J$23,0)) | O27: =INDEX(O$8:O$23,MATCH($J27,$J$8:$J$23,0)) | P27: =INDEX(P$8:P$23,MATCH($J27,$J$8:$J$23,0)) | Q27: =INDEX(Q$8:Q$23,MATCH($J27,$J$8:$J$23,0)) | R27: =INDEX(R$8:R$23,MATCH($J27,$J$8:$J$23,0)) | ... W27: =INDEX(W$8:W$23,MATCH($J27,$J$8:$J$23,0)) | AB27: =ISODD(MAX(COUNTA($D$26:D27)))
D28: 3 | E28: =_xlfn.XLOOKUP($D28,'Rent Roll-Detailed'!$F$8:$F$60,'Rent Roll-Detailed'!$G$8:$G$60) | F28: =_xlfn.XLOOKUP($D28,'Rent Roll-Detailed'!$F$8:$F$60,'Rent Roll-Detailed'!H$8:H$60) | G28: =F28/$F$52 | H28: =IF(E28="Vacant","",_xlfn.XLOOKUP($D28,'Rent Roll-Detailed'!$F$8:$F$60,'Rent Roll-Detailed'!R$8:R$60)) | I28: Yes | J28: =INDEX('One-line RR'!$V$7:$V$12,MATCH('RR Assumptions'!$E28,'One-line RR'!$G$7:$G$12,0)) | K28: =INDEX(K$8:K$23,MATCH($J28,$J$8:$J$23,0)) | L28: =INDEX(L$8:L$23,MATCH($J28,$J$8:$J$23,0)) | M28: =INDEX(M$8:M$23,MATCH($J28,$J$8:$J$23,0)) | N28: =INDEX(N$8:N$23,MATCH($J28,$J$8:$J$23,0)) | O28: =INDEX(O$8:O$23,MATCH($J28,$J$8:$J$23,0)) | P28: =INDEX(P$8:P$23,MATCH($J28,$J$8:$J$23,0)) | Q28: =INDEX(Q$8:Q$23,MATCH($J28,$J$8:$J$23,0)) | R28: =INDEX(R$8:R$23,MATCH($J28,$J$8:$J$23,0)) | ... W28: =INDEX(W$8:W$23,MATCH($J28,$J$8:$J$23,0)) | AB28: =ISODD(MAX(COUNTA($D$26:D28)))
D29: 4 | E29: =_xlfn.XLOOKUP($D29,'Rent Roll-Detailed'!$F$8:$F$60,'Rent Roll-Detailed'!$G$8:$G$60) | F29: =_xlfn.XLOOKUP($D29,'Rent Roll-Detailed'!$F$8:$F$60,'Rent Roll-Detailed'!H$8:H$60) | G29: =F29/$F$52 | H29: =IF(E29="Vacant","",_xlfn.XLOOKUP($D29,'Rent Roll-Detailed'!$F$8:$F$60,'Rent Roll-Detailed'!R$8:R$60)) | I29: No | J29: =INDEX('One-line RR'!$V$7:$V$12,MATCH('RR Assumptions'!$E29,'One-line RR'!$G$7:$G$12,0)) | K29: =INDEX(K$8:K$23,MATCH($J29,$J$8:$J$23,0)) | L29: =INDEX(L$8:L$23,MATCH($J29,$J$8:$J$23,0)) | M29: =INDEX(M$8:M$23,MATCH($J29,$J$8:$J$23,0)) | N29: =INDEX(N$8:N$23,MATCH($J29,$J$8:$J$23,0)) | O29: =INDEX(O$8:O$23,MATCH($J29,$J$8:$J$23,0)) | P29: =INDEX(P$8:P$23,MATCH($J29,$J$8:$J$23,0)) | Q29: =INDEX(Q$8:Q$23,MATCH($J29,$J$8:$J$23,0)) | R29: =INDEX(R$8:R$23,MATCH($J29,$J$8:$J$23,0)) | ... W29: =INDEX(W$8:W$23,MATCH($J29,$J$8:$J$23,0)) | AB29: =ISODD(MAX(COUNTA($D$26:D29)))
D30: 112 | E30: =_xlfn.XLOOKUP($D30,'Rent Roll-Detailed'!$F$8:$F$60,'Rent Roll-Detailed'!$G$8:$G$60) | F30: =_xlfn.XLOOKUP($D30,'Rent Roll-Detailed'!$F$8:$F$60,'Rent Roll-Detailed'!H$8:H$60) | G30: =F30/$F$52 | H30: =IF(E30="Vacant","",_xlfn.XLOOKUP($D30,'Rent Roll-Detailed'!$F$8:$F$60,'Rent Roll-Detailed'!R$8:R$60)) | I30: Yes | J30: =INDEX('One-line RR'!$V$7:$V$12,MATCH('RR Assumptions'!$E30,'One-line RR'!$G$7:$G$12,0)) | K30: =INDEX(K$8:K$23,MATCH($J30,$J$8:$J$23,0)) | L30: =INDEX(L$8:L$23,MATCH($J30,$J$8:$J$23,0)) | M30: =INDEX(M$8:M$23,MATCH($J30,$J$8:$J$23,0)) | N30: =INDEX(N$8:N$23,MATCH($J30,$J$8:$J$23,0)) | O30: =INDEX(O$8:O$23,MATCH($J30,$J$8:$J$23,0)) | P30: =INDEX(P$8:P$23,MATCH($J30,$J$8:$J$23,0)) | Q30: =INDEX(Q$8:Q$23,MATCH($J30,$J$8:$J$23,0)) | R30: =INDEX(R$8:R$23,MATCH($J30,$J$8:$J$23,0)) | ... W30: =INDEX(W$8:W$23,MATCH($J30,$J$8:$J$23,0)) | AB30: =ISODD(MAX(COUNTA($D$26:D30)))
D31: 6 | E31: =_xlfn.XLOOKUP($D31,'Rent Roll-Detailed'!$F$8:$F$60,'Rent Roll-Detailed'!$G$8:$G$60) | F31: =_xlfn.XLOOKUP($D31,'Rent Roll-Detailed'!$F$8:$F$60,'Rent Roll-Detailed'!H$8:H$60) | G31: =F31/$F$52 | H31: =IF(E31="Vacant","",_xlfn.XLOOKUP($D31,'Rent Roll-Detailed'!$F$8:$F$60,'Rent Roll-Detailed'!R$8:R$60)) | I31: Yes | J31: =INDEX('One-line RR'!$V$7:$V$12,MATCH('RR Assumptions'!$E31,'One-line RR'!$G$7:$G$12,0)) | K31: =INDEX(K$8:K$23,MATCH($J31,$J$8:$J$23,0)) | L31: =INDEX(L$8:L$23,MATCH($J31,$J$8:$J$23,0)) | M31: =INDEX(M$8:M$23,MATCH($J31,$J$8:$J$23,0)) | N31: =INDEX(N$8:N$23,MATCH($J31,$J$8:$J$23,0)) | O31: =INDEX(O$8:O$23,MATCH($J31,$J$8:$J$23,0)) | P31: =INDEX(P$8:P$23,MATCH($J31,$J$8:$J$23,0)) | Q31: =INDEX(Q$8:Q$23,MATCH($J31,$J$8:$J$23,0)) | R31: =INDEX(R$8:R$23,MATCH($J31,$J$8:$J$23,0)) | ... W31: =INDEX(W$8:W$23,MATCH($J31,$J$8:$J$23,0)) | AB31: =ISODD(MAX(COUNTA($D$26:D31)))
E32: =_xlfn.XLOOKUP($D32,'Rent Roll-Detailed'!$F$8:$F$60,'Rent Roll-Detailed'!$G$8:$G$60) | F32: =_xlfn.XLOOKUP($D32,'Rent Roll-Detailed'!$F$8:$F$60,'Rent Roll-Detailed'!H$8:H$60) | G32: =F32/$F$52 | H32: =IF(E32="Vacant","",_xlfn.XLOOKUP($D32,'Rent Roll-Detailed'!$F$8:$F$60,'Rent Roll-Detailed'!R$8:R$60)) | I32: Yes | J32: =INDEX('One-line RR'!$V$7:$V$12,MATCH('RR Assumptions'!$E32,'One-line RR'!$G$7:$G$12,0)) | K32: =INDEX(K$8:K$23,MATCH($J32,$J$8:$J$23,0)) | L32: =INDEX(L$8:L$23,MATCH($J32,$J$8:$J$23,0)) | M32: =INDEX(M$8:M$23,MATCH($J32,$J$8:$J$23,0)) | N32: =INDEX(N$8:N$23,MATCH($J32,$J$8:$J$23,0)) | O32: =INDEX(O$8:O$23,MATCH($J32,$J$8:$J$23,0)) | P32: =INDEX(P$8:P$23,MATCH($J32,$J$8:$J$23,0)) | Q32: =INDEX(Q$8:Q$23,MATCH($J32,$J$8:$J$23,0)) | R32: =INDEX(R$8:R$23,MATCH($J32,$J$8:$J$23,0)) | ... W32: =INDEX(W$8:W$23,MATCH($J32,$J$8:$J$23,0)) | AB32: =ISODD(MAX(COUNTA($D$26:D32)))
E33: =_xlfn.XLOOKUP($D33,'Rent Roll-Detailed'!$F$8:$F$60,'Rent Roll-Detailed'!$G$8:$G$60) | F33: =_xlfn.XLOOKUP($D33,'Rent Roll-Detailed'!$F$8:$F$60,'Rent Roll-Detailed'!H$8:H$60) | G33: =F33/$F$52 | H33: =IF(E33="Vacant","",_xlfn.XLOOKUP($D33,'Rent Roll-Detailed'!$F$8:$F$60,'Rent Roll-Detailed'!R$8:R$60)) | I33: No | J33: =INDEX('One-line RR'!$V$7:$V$12,MATCH('RR Assumptions'!$E33,'One-line RR'!$G$7:$G$12,0)) | K33: =INDEX(K$8:K$23,MATCH($J33,$J$8:$J$23,0)) | L33: =INDEX(L$8:L$23,MATCH($J33,$J$8:$J$23,0)) | M33: =INDEX(M$8:M$23,MATCH($J33,$J$8:$J$23,0)) | N33: =INDEX(N$8:N$23,MATCH($J33,$J$8:$J$23,0)) | O33: =INDEX(O$8:O$23,MATCH($J33,$J$8:$J$23,0)) | P33: =INDEX(P$8:P$23,MATCH($J33,$J$8:$J$23,0)) | Q33: =INDEX(Q$8:Q$23,MATCH($J33,$J$8:$J$23,0)) | R33: =INDEX(R$8:R$23,MATCH($J33,$J$8:$J$23,0)) | ... W33: =INDEX(W$8:W$23,MATCH($J33,$J$8:$J$23,0)) | AB33: =ISODD(MAX(COUNTA($D$26:D33)))
E34: =_xlfn.XLOOKUP($D34,'Rent Roll-Detailed'!$F$8:$F$60,'Rent Roll-Detailed'!$G$8:$G$60) | F34: =_xlfn.XLOOKUP($D34,'Rent Roll-Detailed'!$F$8:$F$60,'Rent Roll-Detailed'!H$8:H$60) | G34: =F34/$F$52 | H34: =IF(E34="Vacant","",_xlfn.XLOOKUP($D34,'Rent Roll-Detailed'!$F$8:$F$60,'Rent Roll-Detailed'!R$8:R$60)) | I34: Yes | J34: =INDEX('One-line RR'!$V$7:$V$12,MATCH('RR Assumptions'!$E34,'One-line RR'!$G$7:$G$12,0)) | K34: =INDEX(K$8:K$23,MATCH($J34,$J$8:$J$23,0)) | L34: =INDEX(L$8:L$23,MATCH($J34,$J$8:$J$23,0)) | M34: =INDEX(M$8:M$23,MATCH($J34,$J$8:$J$23,0)) | N34: =INDEX(N$8:N$23,MATCH($J34,$J$8:$J$23,0)) | O34: =INDEX(O$8:O$23,MATCH($J34,$J$8:$J$23,0)) | P34: =INDEX(P$8:P$23,MATCH($J34,$J$8:$J$23,0)) | Q34: =INDEX(Q$8:Q$23,MATCH($J34,$J$8:$J$23,0)) | R34: =INDEX(R$8:R$23,MATCH($J34,$J$8:$J$23,0)) | ... W34: =INDEX(W$8:W$23,MATCH($J34,$J$8:$J$23,0)) | AB34: =ISODD(MAX(COUNTA($D$26:D34)))
E35: =_xlfn.XLOOKUP($D35,'Rent Roll-Detailed'!$F$8:$F$60,'Rent Roll-Detailed'!$G$8:$G$60) | F35: =_xlfn.XLOOKUP($D35,'Rent Roll-Detailed'!$F$8:$F$60,'Rent Roll-Detailed'!H$8:H$60) | G35: =F35/$F$52 | H35: =IF(E35="Vacant","",_xlfn.XLOOKUP($D35,'Rent Roll-Detailed'!$F$8:$F$60,'Rent Roll-Detailed'!R$8:R$60)) | I35: Yes | J35: =INDEX('One-line RR'!$V$7:$V$12,MATCH('RR Assumptions'!$E35,'One-line RR'!$G$7:$G$12,0)) | K35: =INDEX(K$8:K$23,MATCH($J35,$J$8:$J$23,0)) | L35: =INDEX(L$8:L$23,MATCH($J35,$J$8:$J$23,0)) | M35: =INDEX(M$8:M$23,MATCH($J35,$J$8:$J$23,0)) | N35: =INDEX(N$8:N$23,MATCH($J35,$J$8:$J$23,0)) | O35: =INDEX(O$8:O$23,MATCH($J35,$J$8:$J$23,0)) | P35: =INDEX(P$8:P$23,MATCH($J35,$J$8:$J$23,0)) | Q35: =INDEX(Q$8:Q$23,MATCH($J35,$J$8:$J$23,0)) | R35: =INDEX(R$8:R$23,MATCH($J35,$J$8:$J$23,0)) | ... W35: =INDEX(W$8:W$23,MATCH($J35,$J$8:$J$23,0)) | AB35: =ISODD(MAX(COUNTA($D$26:D35)))
E36: =_xlfn.XLOOKUP($D36,'Rent Roll-Detailed'!$F$8:$F$60,'Rent Roll-Detailed'!$G$8:$G$60) | F36: =_xlfn.XLOOKUP($D36,'Rent Roll-Detailed'!$F$8:$F$60,'Rent Roll-Detailed'!H$8:H$60) | G36: =F36/$F$52 | H36: =IF(E36="Vacant","",_xlfn.XLOOKUP($D36,'Rent Roll-Detailed'!$F$8:$F$60,'Rent Roll-Detailed'!R$8:R$60)) | I36: Yes | J36: =INDEX('One-line RR'!$V$7:$V$12,MATCH('RR Assumptions'!$E36,'One-line RR'!$G$7:$G$12,0)) | K36: =INDEX(K$8:K$23,MATCH($J36,$J$8:$J$23,0)) | L36: =INDEX(L$8:L$23,MATCH($J36,$J$8:$J$23,0)) | M36: =INDEX(M$8:M$23,MATCH($J36,$J$8:$J$23,0)) | N36: =INDEX(N$8:N$23,MATCH($J36,$J$8:$J$23,0)) | O36: =INDEX(O$8:O$23,MATCH($J36,$J$8:$J$23,0)) | P36: =INDEX(P$8:P$23,MATCH($J36,$J$8:$J$23,0)) | Q36: =INDEX(Q$8:Q$23,MATCH($J36,$J$8:$J$23,0)) | R36: =INDEX(R$8:R$23,MATCH($J36,$J$8:$J$23,0)) | ... W36: =INDEX(W$8:W$23,MATCH($J36,$J$8:$J$23,0)) | AB36: =ISODD(MAX(COUNTA($D$26:D36)))
E37: =_xlfn.XLOOKUP($D37,'Rent Roll-Detailed'!$F$8:$F$60,'Rent Roll-Detailed'!$G$8:$G$60) | F37: =_xlfn.XLOOKUP($D37,'Rent Roll-Detailed'!$F$8:$F$60,'Rent Roll-Detailed'!H$8:H$60) | G37: =F37/$F$52 | H37: =IF(E37="Vacant","",_xlfn.XLOOKUP($D37,'Rent Roll-Detailed'!$F$8:$F$60,'Rent Roll-Detailed'!R$8:R$60)) | I37: Yes | AB37: =ISODD(MAX(COUNTA($D$26:D37)))
E38: =_xlfn.XLOOKUP($D38,'Rent Roll-Detailed'!$F$8:$F$60,'Rent Roll-Detailed'!$G$8:$G$60) | F38: =_xlfn.XLOOKUP($D38,'Rent Roll-Detailed'!$F$8:$F$60,'Rent Roll-Detailed'!H$8:H$60) | G38: =F38/$F$52 | H38: =IF(E38="Vacant","",_xlfn.XLOOKUP($D38,'Rent Roll-Detailed'!$F$8:$F$60,'Rent Roll-Detailed'!R$8:R$60)) | I38: Yes | J38: =INDEX('One-line RR'!$V$7:$V$12,MATCH('RR Assumptions'!$E38,'One-line RR'!$G$7:$G$12,0)) | K38: =INDEX(K$8:K$23,MATCH($J38,$J$8:$J$23,0)) | L38: =INDEX(L$8:L$23,MATCH($J38,$J$8:$J$23,0)) | M38: =INDEX(M$8:M$23,MATCH($J38,$J$8:$J$23,0)) | N38: =INDEX(N$8:N$23,MATCH($J38,$J$8:$J$23,0)) | O38: =INDEX(O$8:O$23,MATCH($J38,$J$8:$J$23,0)) | P38: =INDEX(P$8:P$23,MATCH($J38,$J$8:$J$23,0)) | Q38: =INDEX(Q$8:Q$23,MATCH($J38,$J$8:$J$23,0)) | R38: =INDEX(R$8:R$23,MATCH($J38,$J$8:$J$23,0)) | ... W38: =INDEX(W$8:W$23,MATCH($J38,$J$8:$J$23,0)) | AB38: =ISODD(MAX(COUNTA($D$26:D38)))
E39: =_xlfn.XLOOKUP($D39,'Rent Roll-Detailed'!$F$8:$F$60,'Rent Roll-Detailed'!$G$8:$G$60) | F39: =_xlfn.XLOOKUP($D39,'Rent Roll-Detailed'!$F$8:$F$60,'Rent Roll-Detailed'!H$8:H$60) | G39: =F39/$F$52 | H39: =IF(E39="Vacant","",_xlfn.XLOOKUP($D39,'Rent Roll-Detailed'!$F$8:$F$60,'Rent Roll-Detailed'!R$8:R$60)) | I39: Yes | J39: =INDEX('One-line RR'!$V$7:$V$12,MATCH('RR Assumptions'!$E39,'One-line RR'!$G$7:$G$12,0)) | K39: =INDEX(K$8:K$23,MATCH($J39,$J$8:$J$23,0)) | L39: =INDEX(L$8:L$23,MATCH($J39,$J$8:$J$23,0)) | M39: =INDEX(M$8:M$23,MATCH($J39,$J$8:$J$23,0)) | N39: =INDEX(N$8:N$23,MATCH($J39,$J$8:$J$23,0)) | O39: =INDEX(O$8:O$23,MATCH($J39,$J$8:$J$23,0)) | P39: =INDEX(P$8:P$23,MATCH($J39,$J$8:$J$23,0)) | Q39: =INDEX(Q$8:Q$23,MATCH($J39,$J$8:$J$23,0)) | R39: =INDEX(R$8:R$23,MATCH($J39,$J$8:$J$23,0)) | ... W39: =INDEX(W$8:W$23,MATCH($J39,$J$8:$J$23,0)) | AB39: =ISODD(MAX(COUNTA($D$26:D39)))
E40: =_xlfn.XLOOKUP($D40,'Rent Roll-Detailed'!$F$8:$F$60,'Rent Roll-Detailed'!$G$8:$G$60) | F40: =_xlfn.XLOOKUP($D40,'Rent Roll-Detailed'!$F$8:$F$60,'Rent Roll-Detailed'!H$8:H$60) | G40: =F40/$F$52 | H40: =IF(E40="Vacant","",_xlfn.XLOOKUP($D40,'Rent Roll-Detailed'!$F$8:$F$60,'Rent Roll-Detailed'!R$8:R$60)) | I40: Yes | J40: =INDEX('One-line RR'!$V$7:$V$12,MATCH('RR Assumptions'!$E40,'One-line RR'!$G$7:$G$12,0)) | K40: =INDEX(K$8:K$23,MATCH($J40,$J$8:$J$23,0)) | L40: =INDEX(L$8:L$23,MATCH($J40,$J$8:$J$23,0)) | M40: =INDEX(M$8:M$23,MATCH($J40,$J$8:$J$23,0)) | N40: =INDEX(N$8:N$23,MATCH($J40,$J$8:$J$23,0)) | O40: =INDEX(O$8:O$23,MATCH($J40,$J$8:$J$23,0)) | P40: =INDEX(P$8:P$23,MATCH($J40,$J$8:$J$23,0)) | Q40: =INDEX(Q$8:Q$23,MATCH($J40,$J$8:$J$23,0)) | R40: =INDEX(R$8:R$23,MATCH($J40,$J$8:$J$23,0)) | S40: =INDEX(S$8:S$23,MATCH($J40,$J$8:$J$23,0)) | T40: 25 | U40: 0 | V40: =INDEX(V$8:V$23,MATCH($J40,$J$8:$J$23,0)) | W40: =INDEX(W$8:W$23,MATCH($J40,$J$8:$J$23,0)) | AB40: =ISODD(MAX(COUNTA($D$26:D40)))
E41: =_xlfn.XLOOKUP($D41,'Rent Roll-Detailed'!$F$8:$F$60,'Rent Roll-Detailed'!$G$8:$G$60) | F41: =_xlfn.XLOOKUP($D41,'Rent Roll-Detailed'!$F$8:$F$60,'Rent Roll-Detailed'!H$8:H$60) | G41: =F41/$F$52 | H41: =IF(E41="Vacant","",_xlfn.XLOOKUP($D41,'Rent Roll-Detailed'!$F$8:$F$60,'Rent Roll-Detailed'!R$8:R$60)) | I41: Yes | J41: =INDEX('One-line RR'!$V$7:$V$12,MATCH('RR Assumptions'!$E41,'One-line RR'!$G$7:$G$12,0)) | K41: =INDEX(K$8:K$23,MATCH($J41,$J$8:$J$23,0)) | L41: =INDEX(L$8:L$23,MATCH($J41,$J$8:$J$23,0)) | M41: =INDEX(M$8:M$23,MATCH($J41,$J$8:$J$23,0)) | N41: =INDEX(N$8:N$23,MATCH($J41,$J$8:$J$23,0)) | O41: =INDEX(O$8:O$23,MATCH($J41,$J$8:$J$23,0)) | P41: =INDEX(P$8:P$23,MATCH($J41,$J$8:$J$23,0)) | Q41: =INDEX(Q$8:Q$23,MATCH($J41,$J$8:$J$23,0)) | R41: =INDEX(R$8:R$23,MATCH($J41,$J$8:$J$23,0)) | S41: =INDEX(S$8:S$23,MATCH($J41,$J$8:$J$23,0)) | T41: 25 | U41: 0 | V41: =INDEX(V$8:V$23,MATCH($J41,$J$8:$J$23,0)) | W41: =INDEX(W$8:W$23,MATCH($J41,$J$8:$J$23,0)) | AB41: =ISODD(MAX(COUNTA($D$26:D41)))
E42: =_xlfn.XLOOKUP($D42,'Rent Roll-Detailed'!$F$8:$F$60,'Rent Roll-Detailed'!$G$8:$G$60) | F42: =_xlfn.XLOOKUP($D42,'Rent Roll-Detailed'!$F$8:$F$60,'Rent Roll-Detailed'!H$8:H$60) | G42: =F42/$F$52 | H42: =IF(E42="Vacant","",_xlfn.XLOOKUP($D42,'Rent Roll-Detailed'!$F$8:$F$60,'Rent Roll-Detailed'!R$8:R$60)) | I42: Yes | J42: =INDEX('One-line RR'!$V$7:$V$12,MATCH('RR Assumptions'!$E42,'One-line RR'!$G$7:$G$12,0)) | K42: =INDEX(K$8:K$23,MATCH($J42,$J$8:$J$23,0)) | L42: =INDEX(L$8:L$23,MATCH($J42,$J$8:$J$23,0)) | M42: =INDEX(M$8:M$23,MATCH($J42,$J$8:$J$23,0)) | N42: =INDEX(N$8:N$23,MATCH($J42,$J$8:$J$23,0)) | O42: =INDEX(O$8:O$23,MATCH($J42,$J$8:$J$23,0)) | P42: =INDEX(P$8:P$23,MATCH($J42,$J$8:$J$23,0)) | Q42: =INDEX(Q$8:Q$23,MATCH($J42,$J$8:$J$23,0)) | R42: =INDEX(R$8:R$23,MATCH($J42,$J$8:$J$23,0)) | S42: =INDEX(S$8:S$23,MATCH($J42,$J$8:$J$23,0)) | T42: 25 | U42: 0 | V42: =INDEX(V$8:V$23,MATCH($J42,$J$8:$J$23,0)) | W42: =INDEX(W$8:W$23,MATCH($J42,$J$8:$J$23,0)) | AB42: =ISODD(MAX(COUNTA($D$26:D42)))
...

Sheet Title Page
C4: Acuity Captal Partners
C12: =Global!G7
C14: =Global!$G$8
C15: =Global!$G$9
C17: =TODAY()

Sheet UW-->

Sheet Annual Cash Flow (2)
C3: ANNUAL CASH FLOW | N3: =Global!G7
E5: 1 | F5: =E5+1 | G5: =F5+1 | H5: =G5+1 | I5: =H5+1 | J5: =I5+1 | K5: =J5+1 | L5: =K5+1 | M5: =L5+1 | N5: =M5+1 | O5: x
E6: 46295 | F6: =EOMONTH(E6,12) | G6: =EOMONTH(F6,12) | H6: =EOMONTH(G6,12) | I6: =EOMONTH(H6,12) | J6: =EOMONTH(I6,12) | K6: =EOMONTH(J6,12) | L6: =EOMONTH(K6,12) | M6: =EOMONTH(L6,12) | N6: =EOMONTH(M6,12) | O6: x
O7: x
D8: INCOME
D9: Base Rental Revenue | E9: #VALUE! | F9: 1437073.8 | G9: 1476520.3 | H9: 1517067.8 | I9: 1558747.3 | J9: 1632879.7 | K9: 1661379.8 | L9: 1707124.2 | M9: 1754148.7 | N9: 1802489.7
D10: Absorption and Turnover Vacancy | E10: 0 | F10: 0 | G10: 0 | H10: 0 | I10: 0 | J10: -549313.44 | K10: 0 | L10: 0 | M10: 0 | N10: 0
D11: Total Scheduled Base Rent | E11: =SUM(E9:E10) | F11: =SUM(F9:F10) | G11: =SUM(G9:G10) | H11: =SUM(H9:H10) | I11: =SUM(I9:I10) | J11: =SUM(J9:J10) | K11: =SUM(K9:K10) | L11: =SUM(L9:L10) | ... N11: =SUM(N9:N10)
D12: CAM Recovery | E12: 0 | F12: 0 | G12: 0 | H12: 0 | I12: 0 | J12: 0 | K12: 0 | L12: 0 | M12: 0 | N12: 0
D13: Realty Tax Recovery | E13: 511673.44 | F13: 527023.68 | G13: 542834.44 | H13: 559119.48 | I13: 575893.04 | J13: 420975.68 | K13: 610964.92 | L13: 629293.8 | M13: 648172.64 | N13: 667617.84
D14: Total Expense Reimbursements | E14: =SUM(E11:E13) | F14: =SUM(F11:F13) | G14: =SUM(G11:G13) | H14: =SUM(H11:H13) | I14: =SUM(I11:I13) | J14: =SUM(J11:J13) | K14: =SUM(K11:K13) | L14: =SUM(L11:L13) | ... N14: =SUM(N11:N13)
D15: Vacancy Loss | E15: -76414.9 | F15: -78563.91 | G15: -80774.21 | H15: -83047.46 | I15: -85385.59 | J15: 0 | K15: -90893.78 | L15: -93456.74 | M15: -96092.89 | N15: -98804.3
D16: Collection Loss | E16: =-E14*0.01 | F16: =-F14*0.01 | G16: =-G14*0.01 | H16: =-H14*0.01 | I16: =-I14*0.01 | J16: =-J14*0.01 | K16: =-K14*0.01 | L16: =-L14*0.01 | ... N16: =-N14*0.01
D17: EFFECTIVE GROSS INCOME | E17: =SUM(E14:E16) | F17: =SUM(F14:F16) | G17: =SUM(G14:G16) | H17: =SUM(H14:H16) | I17: =SUM(I14:I16) | J17: =SUM(J14:J16) | K17: =SUM(K14:K16) | L17: =SUM(L14:L16) | ... N17: =SUM(N14:N16)
E18: 0 | F18: 0 | G18: 0 | H18: 0 | I18: 0 | J18: 0 | K18: 0 | L18: 0 | M18: 0 | N18: 0
D19: OPERATING EXPENSES
D20: Municipal Taxes | E20: 13215 | F20: 30135 | G20: 41952 | H20: 95891 | I20: 17926 | J20: 37915 | K20: 11710 | L20: 27566 | M20: 74283 | N20: 98660
D21: Insurance | E21: 67202 | F21: 59169 | G21: 80194 | H21: 78438 | I21: 20732 | J21: 32059 | K21: 43254 | L21: 61190 | M21: 97266 | N21: 98996
D22: Repairs and Maintenance | E22: 16637 | F22: 16322 | G22: 31147 | H22: 40893 | I22: 74145 | J22: 31668 | K22: 74178 | L22: 75866 | M22: 19263 | N22: 30516
D23: Utilities (Gas) | E23: 89255 | F23: 36123 | G23: 93706 | H23: 14274 | I23: 97467 | J23: 80641 | K23: 35927 | L23: 60622 | M23: 44395 | N23: 59486
D24: Cleaning | E24: 45395 | F24: 22307 | G24: 64842 | H24: 18005 | I24: 95351 | J24: 95944 | K24: 93252 | L24: 97762 | M24: 60413 | N24: 61898
D25: HVAC | E25: 70255 | F25: 69129 | G25: 89995 | H25: 69521 | I25: 23653 | J25: 10319 | K25: 13322 | L25: 67109 | M25: 79706 | N25: 29463
D26: Salaries and Professionals | E26: 29980 | F26: 42152 | G26: 87334 | H26: 74205 | I26: 88937 | J26: 66260 | K26: 54295 | L26: 17869 | M26: 53953 | N26: 51299
D27: Elevator | E27: 34868 | F27: 84190 | G27: 82162 | H27: 15530 | I27: 40924 | J27: 50438 | K27: 18089 | L27: 68001 | M27: 76958 | N27: 89889
D28: Management | E28: 85190 | F28: 77434 | G28: 42582 | H28: 82526 | I28: 24210 | J28: 63921 | K28: 82594 | L28: 76407 | M28: 26649 | N28: 22478
D29: TOTAL OPERATING EXPENSES | E29: =SUM(E20:E28) | F29: =SUM(F20:F28) | G29: =SUM(G20:G28) | H29: =SUM(H20:H28) | I29: =SUM(I20:I28) | J29: =SUM(J20:J28) | K29: =SUM(K20:K28) | L29: =SUM(L20:L28) | ... N29: =SUM(N20:N28)
D31: NET OPERATING INCOME | E31: =E17-E29 | F31: =F17-F29 | G31: =G17-G29 | H31: =H17-H29 | I31: =I17-I29 | J31: =J17-J29 | K31: =K17-K29 | L31: =L17-L29 | ... N31: =N17-N29
E32: 0 | F32: 0 | G32: 0 | H32: 0 | I32: 0 | J32: 0 | K32: 0 | L32: 0 | M32: 0 | N32: 0
D33: LEASING & CAPITAL COSTS
D34: Tenant Improvements | E34: 0 | F34: 0 | G34: 0 | H34: 0 | I34: 0 | J34: 435648.24 | K34: 0 | L34: 0 | M34: 0 | N34: 0
D35: Leasing Commissions | E35: 0 | F35: 0 | G35: 0 | H35: 0 | I35: 0 | J35: 897485.83 | K35: 0 | L35: 0 | M35: 0 | N35: 0
D36: Capital Improvements | E36: 250000 | F36: 250000 | G36: 0 | H36: 0 | I36: 0 | J36: 0 | K36: 0 | L36: 0 | M36: 0 | N36: 0
D37: Capital Reserves | E37: 91697.82 | F37: 94276.7 | G37: 96929.02 | H37: 99656.98 | I37: 102462.73 | J37: 75227.11 | K37: 109072.57 | L37: 112148.04 | M37: 115311.43 | N37: 118565.18
D38: TOTAL LEASING & CAPITAL COSTS | E38: =SUM(E34:E37) | F38: =SUM(F34:F37) | G38: =SUM(G34:G37) | H38: =SUM(H34:H37) | I38: =SUM(I34:I37) | J38: =SUM(J34:J37) | K38: =SUM(K34:K37) | L38: =SUM(L34:L37) | ... N38: =SUM(N34:N37)
D40: UNLEVERAGED CASH FLOW | E40: =E31-E38 | F40: =F31-F38 | G40: =G31-G38 | H40: =H31-H38 | I40: =I31-I38 | J40: =J31-J38 | K40: =K31-K38 | L40: =L31-L38 | ... N40: =N31-N38
E41: 0 | F41: 0 | G41: 0 | H41: 0 | I41: 0 | J41: 0 | K41: 0 | L41: 0 | M41: 0 | N41: 0
D42: DEBT SERVICE
D43: Interest | E43: 123456 | F43: =E43-5900 | G43: =F43-5900 | H43: =G43-5900 | I43: =H43-5900 | J43: =I43-5900 | K43: =J43-5900 | L43: =K43-5900 | M43: =L43-5900 | N43: =M43-5900
D44: Principle | E44: 235985 | F44: =E44+5900 | G44: =F44+5900 | H44: =G44+5900 | I44: =H44+5900 | J44: =I44+5900 | K44: =J44+5900 | L44: =K44+5900 | M44: =L44+5900 | N44: =M44+5900
D45: TOTAL DEBT SERVICE | E45: =SUM(E43:E44) | F45: =SUM(F43:F44) | G45: =SUM(G43:G44) | H45: =SUM(H43:H44) | I45: =SUM(I43:I44) | J45: =SUM(J43:J44) | K45: =SUM(K43:K44) | L45: =SUM(L43:L44) | ... N45: =SUM(N43:N44)
...

Sheet Pres Summ
C3: UW PRESENTATION SUMMARY | H3: =Global!$G$7
F5: VALUATION RANGE
F6: Low | G6: Target | H6: High
D7: Purchase Price | F7: ='Exec Summ'!G21 | G7: ='Exec Summ'!H21 | H7: ='Exec Summ'!I21
D8: Per Square Foot | F8: ='Exec Summ'!G22 | G8: ='Exec Summ'!H22 | H8: ='Exec Summ'!I22
D9: Equity | F9: =F7-$E$27*F7 | G9: =G7-$E$27*G7 | H9: =H7-$E$27*H7
D10: Unleveraged IRR | F10: =VLOOKUP($E$23,'Exec Summ'!$D$30:$I$35,4,0) | G10: =VLOOKUP($E$23,'Exec Summ'!$D$30:$I$35,5,0) | H10: =VLOOKUP($E$23,'Exec Summ'!$D$30:$I$35,6,0)
D11: Leveraged IRR | F11: =VLOOKUP($E$23,'Exec Summ'!$D$38:$I$43,4,0) | G11: =VLOOKUP($E$23,'Exec Summ'!$D$38:$I$43,5,0) | H11: =VLOOKUP($E$23,'Exec Summ'!$D$38:$I$43,6,0)
D12: Year 1 Cash on Cash | F12: ='Sensitivity-Low'!E42 | G12: ='Return Metrics'!H42 | H12: ='Sensitivity-High'!E42
D13: Average Cash on Cash | F13: =AVERAGEIFS('Sensitivity-Low'!$E$42:$N$42,'Sensitivity-Low'!$E$5:$N$5,"<="&$E$23) | G13: =AVERAGEIFS('Return Metrics'!$H$42:$Q$42,'Return Metrics'!$H$5:$Q$5,"<="&$E$23) | H13: =AVERAGEIFS('Sensitivity-High'!$E$42:$N$42,'Sensitivity-High'!$E$5:$N$5,"<="&$E$23)
D15: Cap Rates
D16: In-Place Cap Rate | F16: ='Exec Summ'!G25 | G16: ='Exec Summ'!H25 | H16: ='Exec Summ'!I25
D17: Year 1 Cap Rate | F17: ='Exec Summ'!G26 | G17: ='Exec Summ'!H26 | H17: ='Exec Summ'!I26
D18: Stabilized Year 3 YOC | F18: ='Exec Summ'!G27 | G18: ='Exec Summ'!H27 | H18: ='Exec Summ'!I27
D20: Purchase/Exit Assumptions: | G20: General Assumptions:
D21: Exit Cap Rate | E21: ='Exec Summ'!F7 | G21: Rentable SF | H21: ='Exec Summ'!J7
D22: Cost of Exit Sale | E22: ='Exec Summ'!F9 | G22: In-Place Occupancy | H22: ='Exec Summ'!J8
D23: Hold Period | E23: ='Exec Summ'!F10 | G23: Yr. 1 Occupancy | H23: ='Exec Summ'!J9
G24: In-Place NOI (Month 1) | H24: ='Exec Summ'!J10
D26: Financing: | G26: Purchase Price / Funding
D27: Loan to Value | E27: ='Exec Summ'!F13 | G27: Purchase Price | H27: =G7
D28: Mid-Range Value | E28: ='Exec Summ'!F14 | G28: Debt | H28: =-E29
D29: Loan Amount | E29: ='Exec Summ'!F15 | G29: Equity | H29: =SUM(H27:H28)
D30: Amortization (Months) | E30: ='Exec Summ'!F16
D31: Interest Rate | E31: ='Exec Summ'!F17
D32: Interest Only (Months) | E32: ='Exec Summ'!F18

Sheet Exec Summ
D3: EXECUTIVE SUMMARY | P3: =Global!$G$7
E6: Purchase/Exit Assumptions: | H6: General Assumptions: | L6: Exit Cap Rate Sensitivity | N6: =O6-0.005 | O6: =F7 | P6: =O6+0.005
E7: Exit Cap Rate | F7: 0.085 | H7: Rentable SF | J7: =Global!G18 | L7: =$H$21
E8: Closing/Acq Costs | F8: 0.01 | H8: In-Place Occupancy | J8: =Global!G19 | L8: 3-Year UIRR | N8: =Z262 | O8: =H30 | P8: =AA262
E9: Cost of Exit Sale | F9: 0.02 | H9: Yr. 1 Occupancy | J9: ='Lease Audit '!C16 | L9: 5-Year UIRR | N9: =Z264 | O9: =H32 | P9: =AA264
E10: Hold Period | F10: 5 | H10: In-Place NOI (Month 1) | J10: =SUMIFS('Cash flow'!P:P,'Cash flow'!$A:$A,"Net Operating Income")*12 | L10: 7-Year UIRR | N10: =Z266 | O10: =H34 | P10: =AA266
E12: Financing: | H12: Loan Funding Schedule:
E13: Loan to Value | F13: 0.6 | H13: At Purchase | J13: ='Loan Calculation'!C6
E14: Mid-Range Value | F14: =H21 | H14: Year 1 (From Escrow) | J14: ='Loan Calculation'!K27
E15: Loan Amount | F15: =F14*F13 | H15: Year 2 (From Escrow) | J15: ='Loan Calculation'!K39
E16: Amortization (Months) | F16: =30*12 | H16: Year 3 (From Escrow) | J16: ='Loan Calculation'!K51
E17: Interest Rate | F17: 0.0675 | H17: Year 4 (From Escrow) | J17: ='Loan Calculation'!K63
E18: Interest Only (Months) | F18: 0 | H18: Total | J18: =SUM(J13:J17)
E21: PURCHASE PRICE | G21: =H21-$J$22 | H21: 16250000 | I21: =H21+$J$22 | J21: Increments:
E22: Per Square Foot | G22: =G21/$J$7 | H22: =H21/$J$7 | I22: =I21/$J$7 | J22: 250000
E24: Cap Rates
E25: In-Place Cap Rate | G25: =$J$10/G21 | H25: =$J$10/H21 | I25: =$J$10/I21
E26: Year 1 Cap Rate | G26: =$G$47/G21 | H26: =$G$47/H21 | I26: =$G$47/I21
E27: Year 3 Cap Rate | G27: =Proforma!$H$44/'Exec Summ'!G21 | H27: =Proforma!$H$44/'Exec Summ'!H21 | I27: =Proforma!$H$44/'Exec Summ'!I21
J28: IRR Breakdown:
E29: IRR Range - Unleveraged | J29: Cash Flow | K29: Exit Sale
D30: 3 | E30: 3-Year IRR | G30: =VLOOKUP($D30,'Sensitivity-Low'!$A$26:$C$31,3,0) | H30: =VLOOKUP($D30,'Return Metrics'!$D$26:$F$31,3,0) | I30: =VLOOKUP($D30,'Sensitivity-High'!$A$26:$C$31,3,0) | J30: =M82 | K30: =P82
D31: 4 | E31: 4-Year IRR | G31: =VLOOKUP($D31,'Sensitivity-Low'!$A$26:$C$31,3,0) | H31: =VLOOKUP($D31,'Return Metrics'!$D$26:$F$31,3,0) | I31: =VLOOKUP($D31,'Sensitivity-High'!$A$26:$C$31,3,0) | J31: =M93 | K31: =P93
D32: 5 | E32: 5-Year IRR | G32: =VLOOKUP($D32,'Sensitivity-Low'!$A$26:$C$31,3,0) | H32: =VLOOKUP($D32,'Return Metrics'!$D$26:$F$31,3,0) | I32: =VLOOKUP($D32,'Sensitivity-High'!$A$26:$C$31,3,0) | J32: =M105 | K32: =P105
D33: 6 | E33: 6-Year IRR | G33: =VLOOKUP($D33,'Sensitivity-Low'!$A$26:$C$31,3,0) | H33: =VLOOKUP($D33,'Return Metrics'!$D$26:$F$31,3,0) | I33: =VLOOKUP($D33,'Sensitivity-High'!$A$26:$C$31,3,0) | J33: =M118 | K33: =P118
D34: 7 | E34: 7-Year IRR | G34: =VLOOKUP($D34,'Sensitivity-Low'!$A$26:$C$31,3,0) | H34: =VLOOKUP($D34,'Return Metrics'!$D$26:$F$31,3,0) | I34: =VLOOKUP($D34,'Sensitivity-High'!$A$26:$C$31,3,0) | J34: =M132 | K34: =P132
D35: 10 | E35: 10-Year IRR | G35: =VLOOKUP($D35,'Sensitivity-Low'!$A$26:$C$31,3,0) | H35: =VLOOKUP($D35,'Return Metrics'!$D$26:$F$31,3,0) | I35: =VLOOKUP($D35,'Sensitivity-High'!$A$26:$C$31,3,0) | J35: =M149 | K35: =P149
E37: IRR Range - Leveraged
D38: 3 | E38: 3-Year IRR | G38: =VLOOKUP($D38,'Sensitivity-Low'!$A$48:$C$53,3,0) | H38: =VLOOKUP($D38,'Return Metrics'!$D$48:$F$53,3,0) | I38: =VLOOKUP($D38,'Sensitivity-High'!$A$48:$C$53,3,0)
D39: 4 | E39: 4-Year IRR | G39: =VLOOKUP($D39,'Sensitivity-Low'!$A$48:$C$53,3,0) | H39: =VLOOKUP($D39,'Return Metrics'!$D$48:$F$53,3,0) | I39: =VLOOKUP($D39,'Sensitivity-High'!$A$48:$C$53,3,0)
D40: 5 | E40: 5-Year IRR | G40: =VLOOKUP($D40,'Sensitivity-Low'!$A$48:$C$53,3,0) | H40: =VLOOKUP($D40,'Return Metrics'!$D$48:$F$53,3,0) | I40: =VLOOKUP($D40,'Sensitivity-High'!$A$48:$C$53,3,0)
D41: 6 | E41: 6-Year IRR | G41: =VLOOKUP($D41,'Sensitivity-Low'!$A$48:$C$53,3,0) | H41: =VLOOKUP($D41,'Return Metrics'!$D$48:$F$53,3,0) | I41: =VLOOKUP($D41,'Sensitivity-High'!$A$48:$C$53,3,0)
D42: 7 | E42: 7-Year IRR | G42: =VLOOKUP($D42,'Sensitivity-Low'!$A$48:$C$53,3,0) | H42: =VLOOKUP($D42,'Return Metrics'!$D$48:$F$53,3,0) | I42: =VLOOKUP($D42,'Sensitivity-High'!$A$48:$C$53,3,0)
D43: 10 | E43: 10-Year IRR | G43: =VLOOKUP($D43,'Sensitivity-Low'!$A$48:$C$53,3,0) | H43: =VLOOKUP($D43,'Return Metrics'!$D$48:$F$53,3,0) | I43: =VLOOKUP($D43,'Sensitivity-High'!$A$48:$C$53,3,0)
E45: CASH FLOW | F45: Purchase | G45: Year 1 | H45: Year 2 | I45: Year 3 | J45: Year 4 | K45: Year 5 | L45: Year 6 | M45: Year 7 | N45: Year 8 | O45: Year 9 | P45: Year 10 | R45: Year 11
E46: Purchase Price | F46: =-H21*(1+F8)
E47: Net Operating Income | G47: =SUMIFS('Cash flow'!C:C,'Cash flow'!$A:$A,$E$47) | H47: =SUMIFS('Cash flow'!D:D,'Cash flow'!$A:$A,$E$47) | I47: =SUMIFS('Cash flow'!E:E,'Cash flow'!$A:$A,$E$47) | J47: =SUMIFS('Cash flow'!F:F,'Cash flow'!$A:$A,$E$47) | K47: =SUMIFS('Cash flow'!G:G,'Cash flow'!$A:$A,$E$47) | L47: =SUMIFS('Cash flow'!H:H,'Cash flow'!$A:$A,$E$47) | M47: =SUMIFS('Cash flow'!I:I,'Cash flow'!$A:$A,$E$47) | N47: =SUMIFS('Cash flow'!J:J,'Cash flow'!$A:$A,$E$47) | O47: =SUMIFS('Cash flow'!K:K,'Cash flow'!$A:$A,$E$47) | P47: =SUMIFS('Cash flow'!L:L,'Cash flow'!$A:$A,$E$47) | R47: =SUMIFS('Cash flow'!M:M,'Cash flow'!$A:$A,$E$47)
E48: Total Leasing & Capital Costs | G48: =SUMIFS('Cash flow'!C:C,'Cash flow'!$A:$A,$E$48) | H48: =SUMIFS('Cash flow'!D:D,'Cash flow'!$A:$A,$E$48) | I48: =SUMIFS('Cash flow'!E:E,'Cash flow'!$A:$A,$E$48) | J48: =SUMIFS('Cash flow'!F:F,'Cash flow'!$A:$A,$E$48) | K48: =SUMIFS('Cash flow'!G:G,'Cash flow'!$A:$A,$E$48) | L48: =SUMIFS('Cash flow'!H:H,'Cash flow'!$A:$A,$E$48) | M48: =SUMIFS('Cash flow'!I:I,'Cash flow'!$A:$A,$E$48) | N48: =SUMIFS('Cash flow'!J:J,'Cash flow'!$A:$A,$E$48) | O48: =SUMIFS('Cash flow'!K:K,'Cash flow'!$A:$A,$E$48) | P48: =SUMIFS('Cash flow'!L:L,'Cash flow'!$A:$A,$E$48)
E49: Unleveraged Cash Flow | G49: =G47-G48 | H49: =H47-H48 | I49: =I47-I48 | J49: =J47-J48 | K49: =K47-K48 | L49: =L47-L48 | M49: =M47-M48 | N49: =N47-N48 | ... P49: =P47-P48
E50: Loan Funding | F50: ='Return Metrics'!G39 | G50: ='Return Metrics'!H39 | H50: ='Return Metrics'!I39 | I50: ='Return Metrics'!J39 | J50: ='Return Metrics'!K39
...

Sheet Annual Cash Flow (3)
C3: ANNUAL CASH FLOW | N3: =Global!G7
E5: 1 | F5: =E5+1 | G5: =F5+1 | H5: =G5+1 | I5: =H5+1 | J5: =I5+1 | K5: =J5+1 | L5: =K5+1 | M5: =L5+1 | N5: =M5+1 | O5: x
E6: 46295 | F6: =EOMONTH(E6,12) | G6: =EOMONTH(F6,12) | H6: =EOMONTH(G6,12) | I6: =EOMONTH(H6,12) | J6: =EOMONTH(I6,12) | K6: =EOMONTH(J6,12) | L6: =EOMONTH(K6,12) | M6: =EOMONTH(L6,12) | N6: =EOMONTH(M6,12) | O6: x
O7: x
D8: INCOME
D9: Base Rental Revenue | E9: =SUMIFS(Proforma!F:F,Proforma!$D:$D,'Annual Cash Flow (3)'!$D9) | F9: =SUMIFS(Proforma!G:G,Proforma!$D:$D,'Annual Cash Flow (3)'!$D9) | G9: =SUMIFS(Proforma!H:H,Proforma!$D:$D,'Annual Cash Flow (3)'!$D9) | H9: =SUMIFS(Proforma!I:I,Proforma!$D:$D,'Annual Cash Flow (3)'!$D9) | I9: =SUMIFS(Proforma!J:J,Proforma!$D:$D,'Annual Cash Flow (3)'!$D9) | J9: =SUMIFS(Proforma!K:K,Proforma!$D:$D,'Annual Cash Flow (3)'!$D9) | K9: =SUMIFS(Proforma!L:L,Proforma!$D:$D,'Annual Cash Flow (3)'!$D9) | L9: =SUMIFS(Proforma!M:M,Proforma!$D:$D,'Annual Cash Flow (3)'!$D9) | M9: =SUMIFS(Proforma!N:N,Proforma!$D:$D,'Annual Cash Flow (3)'!$D9) | N9: =SUMIFS(Proforma!O:O,Proforma!$D:$D,'Annual Cash Flow (3)'!$D9)
D10: Absorption and Turnover Vacancy | E10: =SUMIFS(Proforma!F:F,Proforma!$D:$D,'Annual Cash Flow (3)'!$D10) | F10: =SUMIFS(Proforma!G:G,Proforma!$D:$D,'Annual Cash Flow (3)'!$D10) | G10: =SUMIFS(Proforma!H:H,Proforma!$D:$D,'Annual Cash Flow (3)'!$D10) | H10: =SUMIFS(Proforma!I:I,Proforma!$D:$D,'Annual Cash Flow (3)'!$D10) | I10: =SUMIFS(Proforma!J:J,Proforma!$D:$D,'Annual Cash Flow (3)'!$D10) | J10: =SUMIFS(Proforma!K:K,Proforma!$D:$D,'Annual Cash Flow (3)'!$D10) | K10: =SUMIFS(Proforma!L:L,Proforma!$D:$D,'Annual Cash Flow (3)'!$D10) | L10: =SUMIFS(Proforma!M:M,Proforma!$D:$D,'Annual Cash Flow (3)'!$D10) | M10: =SUMIFS(Proforma!N:N,Proforma!$D:$D,'Annual Cash Flow (3)'!$D10) | N10: =SUMIFS(Proforma!O:O,Proforma!$D:$D,'Annual Cash Flow (3)'!$D10)
D11: Total Scheduled Base Rent | E11: =SUM(E9:E10) | F11: =SUM(F9:F10) | G11: =SUM(G9:G10) | H11: =SUM(H9:H10) | I11: =SUM(I9:I10) | J11: =SUM(J9:J10) | K11: =SUM(K9:K10) | L11: =SUM(L9:L10) | ... N11: =SUM(N9:N10)
D12: CAM Recovery | E12: =SUMIFS(Proforma!F:F,Proforma!$D:$D,'Annual Cash Flow (3)'!$D12) | F12: =SUMIFS(Proforma!G:G,Proforma!$D:$D,'Annual Cash Flow (3)'!$D12) | G12: =SUMIFS(Proforma!H:H,Proforma!$D:$D,'Annual Cash Flow (3)'!$D12) | H12: =SUMIFS(Proforma!I:I,Proforma!$D:$D,'Annual Cash Flow (3)'!$D12) | I12: =SUMIFS(Proforma!J:J,Proforma!$D:$D,'Annual Cash Flow (3)'!$D12) | J12: =SUMIFS(Proforma!K:K,Proforma!$D:$D,'Annual Cash Flow (3)'!$D12) | K12: =SUMIFS(Proforma!L:L,Proforma!$D:$D,'Annual Cash Flow (3)'!$D12) | L12: =SUMIFS(Proforma!M:M,Proforma!$D:$D,'Annual Cash Flow (3)'!$D12) | M12: =SUMIFS(Proforma!N:N,Proforma!$D:$D,'Annual Cash Flow (3)'!$D12) | N12: =SUMIFS(Proforma!O:O,Proforma!$D:$D,'Annual Cash Flow (3)'!$D12)
D13: Realty Tax Recovery | E13: =SUMIFS(Proforma!F:F,Proforma!$D:$D,'Annual Cash Flow (3)'!$D13) | F13: =SUMIFS(Proforma!G:G,Proforma!$D:$D,'Annual Cash Flow (3)'!$D13) | G13: =SUMIFS(Proforma!H:H,Proforma!$D:$D,'Annual Cash Flow (3)'!$D13) | H13: =SUMIFS(Proforma!I:I,Proforma!$D:$D,'Annual Cash Flow (3)'!$D13) | I13: =SUMIFS(Proforma!J:J,Proforma!$D:$D,'Annual Cash Flow (3)'!$D13) | J13: =SUMIFS(Proforma!K:K,Proforma!$D:$D,'Annual Cash Flow (3)'!$D13) | K13: =SUMIFS(Proforma!L:L,Proforma!$D:$D,'Annual Cash Flow (3)'!$D13) | L13: =SUMIFS(Proforma!M:M,Proforma!$D:$D,'Annual Cash Flow (3)'!$D13) | M13: =SUMIFS(Proforma!N:N,Proforma!$D:$D,'Annual Cash Flow (3)'!$D13) | N13: =SUMIFS(Proforma!O:O,Proforma!$D:$D,'Annual Cash Flow (3)'!$D13)
D14: Total Expense Reimbursements | E14: =SUM(E11:E13) | F14: =SUM(F11:F13) | G14: =SUM(G11:G13) | H14: =SUM(H11:H13) | I14: =SUM(I11:I13) | J14: =SUM(J11:J13) | K14: =SUM(K11:K13) | L14: =SUM(L11:L13) | ... N14: =SUM(N11:N13)
D15: Parking Revenue | E15: =SUMIFS(Proforma!F:F,Proforma!$D:$D,'Annual Cash Flow (3)'!$D15) | F15: =SUMIFS(Proforma!G:G,Proforma!$D:$D,'Annual Cash Flow (3)'!$D15) | G15: =SUMIFS(Proforma!H:H,Proforma!$D:$D,'Annual Cash Flow (3)'!$D15) | H15: =SUMIFS(Proforma!I:I,Proforma!$D:$D,'Annual Cash Flow (3)'!$D15) | I15: =SUMIFS(Proforma!J:J,Proforma!$D:$D,'Annual Cash Flow (3)'!$D15) | J15: =SUMIFS(Proforma!K:K,Proforma!$D:$D,'Annual Cash Flow (3)'!$D15) | K15: =SUMIFS(Proforma!L:L,Proforma!$D:$D,'Annual Cash Flow (3)'!$D15) | L15: =SUMIFS(Proforma!M:M,Proforma!$D:$D,'Annual Cash Flow (3)'!$D15) | M15: =SUMIFS(Proforma!N:N,Proforma!$D:$D,'Annual Cash Flow (3)'!$D15) | N15: =SUMIFS(Proforma!O:O,Proforma!$D:$D,'Annual Cash Flow (3)'!$D15)
D16: Total Gross Revenue | E16: =SUM(E14:E15) | F16: =SUM(F14:F15) | G16: =SUM(G14:G15) | H16: =SUM(H14:H15) | I16: =SUM(I14:I15) | J16: =SUM(J14:J15) | K16: =SUM(K14:K15) | L16: =SUM(L14:L15) | ... N16: =SUM(N14:N15)
D17: General Vacancy Loss | E17: =SUMIFS(Proforma!F:F,Proforma!$D:$D,'Annual Cash Flow (3)'!$D17) | F17: =SUMIFS(Proforma!G:G,Proforma!$D:$D,'Annual Cash Flow (3)'!$D17) | G17: =SUMIFS(Proforma!H:H,Proforma!$D:$D,'Annual Cash Flow (3)'!$D17) | H17: =SUMIFS(Proforma!I:I,Proforma!$D:$D,'Annual Cash Flow (3)'!$D17) | I17: =SUMIFS(Proforma!J:J,Proforma!$D:$D,'Annual Cash Flow (3)'!$D17) | J17: =SUMIFS(Proforma!K:K,Proforma!$D:$D,'Annual Cash Flow (3)'!$D17) | K17: =SUMIFS(Proforma!L:L,Proforma!$D:$D,'Annual Cash Flow (3)'!$D17) | L17: =SUMIFS(Proforma!M:M,Proforma!$D:$D,'Annual Cash Flow (3)'!$D17) | M17: =SUMIFS(Proforma!N:N,Proforma!$D:$D,'Annual Cash Flow (3)'!$D17) | N17: =SUMIFS(Proforma!O:O,Proforma!$D:$D,'Annual Cash Flow (3)'!$D17)
D18: EFFECTIVE GROSS INCOME | E18: =SUM(E16:E17) | F18: =SUM(F16:F17) | G18: =SUM(G16:G17) | H18: =SUM(H16:H17) | I18: =SUM(I16:I17) | J18: =SUM(J16:J17) | K18: =SUM(K16:K17) | L18: =SUM(L16:L17) | ... N18: =SUM(N16:N17)
E19: 0 | F19: 0 | G19: 0 | H19: 0 | I19: 0 | J19: 0 | K19: 0 | L19: 0 | M19: 0 | N19: 0
D20: OPERATING EXPENSES
D21: Municipal Taxes | E21: =SUMIFS(Proforma!F:F,Proforma!$D:$D,'Annual Cash Flow (3)'!$D21) | F21: =SUMIFS(Proforma!G:G,Proforma!$D:$D,'Annual Cash Flow (3)'!$D21) | G21: =SUMIFS(Proforma!H:H,Proforma!$D:$D,'Annual Cash Flow (3)'!$D21) | H21: =SUMIFS(Proforma!I:I,Proforma!$D:$D,'Annual Cash Flow (3)'!$D21) | I21: =SUMIFS(Proforma!J:J,Proforma!$D:$D,'Annual Cash Flow (3)'!$D21) | J21: =SUMIFS(Proforma!K:K,Proforma!$D:$D,'Annual Cash Flow (3)'!$D21) | K21: =SUMIFS(Proforma!L:L,Proforma!$D:$D,'Annual Cash Flow (3)'!$D21) | L21: =SUMIFS(Proforma!M:M,Proforma!$D:$D,'Annual Cash Flow (3)'!$D21) | M21: =SUMIFS(Proforma!N:N,Proforma!$D:$D,'Annual Cash Flow (3)'!$D21) | N21: =SUMIFS(Proforma!O:O,Proforma!$D:$D,'Annual Cash Flow (3)'!$D21)
D22: Insurance | E22: =SUMIFS(Proforma!F:F,Proforma!$D:$D,'Annual Cash Flow (3)'!$D22) | F22: =SUMIFS(Proforma!G:G,Proforma!$D:$D,'Annual Cash Flow (3)'!$D22) | G22: =SUMIFS(Proforma!H:H,Proforma!$D:$D,'Annual Cash Flow (3)'!$D22) | H22: =SUMIFS(Proforma!I:I,Proforma!$D:$D,'Annual Cash Flow (3)'!$D22) | I22: =SUMIFS(Proforma!J:J,Proforma!$D:$D,'Annual Cash Flow (3)'!$D22) | J22: =SUMIFS(Proforma!K:K,Proforma!$D:$D,'Annual Cash Flow (3)'!$D22) | K22: =SUMIFS(Proforma!L:L,Proforma!$D:$D,'Annual Cash Flow (3)'!$D22) | L22: =SUMIFS(Proforma!M:M,Proforma!$D:$D,'Annual Cash Flow (3)'!$D22) | M22: =SUMIFS(Proforma!N:N,Proforma!$D:$D,'Annual Cash Flow (3)'!$D22) | N22: =SUMIFS(Proforma!O:O,Proforma!$D:$D,'Annual Cash Flow (3)'!$D22)
D23: Repairs and Maintenance | E23: =SUMIFS(Proforma!F:F,Proforma!$D:$D,'Annual Cash Flow (3)'!$D23) | F23: =SUMIFS(Proforma!G:G,Proforma!$D:$D,'Annual Cash Flow (3)'!$D23) | G23: =SUMIFS(Proforma!H:H,Proforma!$D:$D,'Annual Cash Flow (3)'!$D23) | H23: =SUMIFS(Proforma!I:I,Proforma!$D:$D,'Annual Cash Flow (3)'!$D23) | I23: =SUMIFS(Proforma!J:J,Proforma!$D:$D,'Annual Cash Flow (3)'!$D23) | J23: =SUMIFS(Proforma!K:K,Proforma!$D:$D,'Annual Cash Flow (3)'!$D23) | K23: =SUMIFS(Proforma!L:L,Proforma!$D:$D,'Annual Cash Flow (3)'!$D23) | L23: =SUMIFS(Proforma!M:M,Proforma!$D:$D,'Annual Cash Flow (3)'!$D23) | M23: =SUMIFS(Proforma!N:N,Proforma!$D:$D,'Annual Cash Flow (3)'!$D23) | N23: =SUMIFS(Proforma!O:O,Proforma!$D:$D,'Annual Cash Flow (3)'!$D23)
D24: Utilities (Gas) | E24: =SUMIFS(Proforma!F:F,Proforma!$D:$D,'Annual Cash Flow (3)'!$D24) | F24: =SUMIFS(Proforma!G:G,Proforma!$D:$D,'Annual Cash Flow (3)'!$D24) | G24: =SUMIFS(Proforma!H:H,Proforma!$D:$D,'Annual Cash Flow (3)'!$D24) | H24: =SUMIFS(Proforma!I:I,Proforma!$D:$D,'Annual Cash Flow (3)'!$D24) | I24: =SUMIFS(Proforma!J:J,Proforma!$D:$D,'Annual Cash Flow (3)'!$D24) | J24: =SUMIFS(Proforma!K:K,Proforma!$D:$D,'Annual Cash Flow (3)'!$D24) | K24: =SUMIFS(Proforma!L:L,Proforma!$D:$D,'Annual Cash Flow (3)'!$D24) | L24: =SUMIFS(Proforma!M:M,Proforma!$D:$D,'Annual Cash Flow (3)'!$D24) | M24: =SUMIFS(Proforma!N:N,Proforma!$D:$D,'Annual Cash Flow (3)'!$D24) | N24: =SUMIFS(Proforma!O:O,Proforma!$D:$D,'Annual Cash Flow (3)'!$D24)
D25: Cleaning | E25: =SUMIFS(Proforma!F:F,Proforma!$D:$D,'Annual Cash Flow (3)'!$D25) | F25: =SUMIFS(Proforma!G:G,Proforma!$D:$D,'Annual Cash Flow (3)'!$D25) | G25: =SUMIFS(Proforma!H:H,Proforma!$D:$D,'Annual Cash Flow (3)'!$D25) | H25: =SUMIFS(Proforma!I:I,Proforma!$D:$D,'Annual Cash Flow (3)'!$D25) | I25: =SUMIFS(Proforma!J:J,Proforma!$D:$D,'Annual Cash Flow (3)'!$D25) | J25: =SUMIFS(Proforma!K:K,Proforma!$D:$D,'Annual Cash Flow (3)'!$D25) | K25: =SUMIFS(Proforma!L:L,Proforma!$D:$D,'Annual Cash Flow (3)'!$D25) | L25: =SUMIFS(Proforma!M:M,Proforma!$D:$D,'Annual Cash Flow (3)'!$D25) | M25: =SUMIFS(Proforma!N:N,Proforma!$D:$D,'Annual Cash Flow (3)'!$D25) | N25: =SUMIFS(Proforma!O:O,Proforma!$D:$D,'Annual Cash Flow (3)'!$D25)
D26: HVAC | E26: =SUMIFS(Proforma!F:F,Proforma!$D:$D,'Annual Cash Flow (3)'!$D26) | F26: =SUMIFS(Proforma!G:G,Proforma!$D:$D,'Annual Cash Flow (3)'!$D26) | G26: =SUMIFS(Proforma!H:H,Proforma!$D:$D,'Annual Cash Flow (3)'!$D26) | H26: =SUMIFS(Proforma!I:I,Proforma!$D:$D,'Annual Cash Flow (3)'!$D26) | I26: =SUMIFS(Proforma!J:J,Proforma!$D:$D,'Annual Cash Flow (3)'!$D26) | J26: =SUMIFS(Proforma!K:K,Proforma!$D:$D,'Annual Cash Flow (3)'!$D26) | K26: =SUMIFS(Proforma!L:L,Proforma!$D:$D,'Annual Cash Flow (3)'!$D26) | L26: =SUMIFS(Proforma!M:M,Proforma!$D:$D,'Annual Cash Flow (3)'!$D26) | M26: =SUMIFS(Proforma!N:N,Proforma!$D:$D,'Annual Cash Flow (3)'!$D26) | N26: =SUMIFS(Proforma!O:O,Proforma!$D:$D,'Annual Cash Flow (3)'!$D26)
D27: Salaries and Professionals | E27: =SUMIFS(Proforma!F:F,Proforma!$D:$D,'Annual Cash Flow (3)'!$D27) | F27: =SUMIFS(Proforma!G:G,Proforma!$D:$D,'Annual Cash Flow (3)'!$D27) | G27: =SUMIFS(Proforma!H:H,Proforma!$D:$D,'Annual Cash Flow (3)'!$D27) | H27: =SUMIFS(Proforma!I:I,Proforma!$D:$D,'Annual Cash Flow (3)'!$D27) | I27: =SUMIFS(Proforma!J:J,Proforma!$D:$D,'Annual Cash Flow (3)'!$D27) | J27: =SUMIFS(Proforma!K:K,Proforma!$D:$D,'Annual Cash Flow (3)'!$D27) | K27: =SUMIFS(Proforma!L:L,Proforma!$D:$D,'Annual Cash Flow (3)'!$D27) | L27: =SUMIFS(Proforma!M:M,Proforma!$D:$D,'Annual Cash Flow (3)'!$D27) | M27: =SUMIFS(Proforma!N:N,Proforma!$D:$D,'Annual Cash Flow (3)'!$D27) | N27: =SUMIFS(Proforma!O:O,Proforma!$D:$D,'Annual Cash Flow (3)'!$D27)
D28: Elevator | E28: =SUMIFS(Proforma!F:F,Proforma!$D:$D,'Annual Cash Flow (3)'!$D28) | F28: =SUMIFS(Proforma!G:G,Proforma!$D:$D,'Annual Cash Flow (3)'!$D28) | G28: =SUMIFS(Proforma!H:H,Proforma!$D:$D,'Annual Cash Flow (3)'!$D28) | H28: =SUMIFS(Proforma!I:I,Proforma!$D:$D,'Annual Cash Flow (3)'!$D28) | I28: =SUMIFS(Proforma!J:J,Proforma!$D:$D,'Annual Cash Flow (3)'!$D28) | J28: =SUMIFS(Proforma!K:K,Proforma!$D:$D,'Annual Cash Flow (3)'!$D28) | K28: =SUMIFS(Proforma!L:L,Proforma!$D:$D,'Annual Cash Flow (3)'!$D28) | L28: =SUMIFS(Proforma!M:M,Proforma!$D:$D,'Annual Cash Flow (3)'!$D28) | M28: =SUMIFS(Proforma!N:N,Proforma!$D:$D,'Annual Cash Flow (3)'!$D28) | N28: =SUMIFS(Proforma!O:O,Proforma!$D:$D,'Annual Cash Flow (3)'!$D28)
D29: Management | E29: =SUMIFS(Proforma!F:F,Proforma!$D:$D,'Annual Cash Flow (3)'!$D29) | F29: =SUMIFS(Proforma!G:G,Proforma!$D:$D,'Annual Cash Flow (3)'!$D29) | G29: =SUMIFS(Proforma!H:H,Proforma!$D:$D,'Annual Cash Flow (3)'!$D29) | H29: =SUMIFS(Proforma!I:I,Proforma!$D:$D,'Annual Cash Flow (3)'!$D29) | I29: =SUMIFS(Proforma!J:J,Proforma!$D:$D,'Annual Cash Flow (3)'!$D29) | J29: =SUMIFS(Proforma!K:K,Proforma!$D:$D,'Annual Cash Flow (3)'!$D29) | K29: =SUMIFS(Proforma!L:L,Proforma!$D:$D,'Annual Cash Flow (3)'!$D29) | L29: =SUMIFS(Proforma!M:M,Proforma!$D:$D,'Annual Cash Flow (3)'!$D29) | M29: =SUMIFS(Proforma!N:N,Proforma!$D:$D,'Annual Cash Flow (3)'!$D29) | N29: =SUMIFS(Proforma!O:O,Proforma!$D:$D,'Annual Cash Flow (3)'!$D29)
D30: TOTAL OPERATING EXPENSES | E30: =SUM(E21:E29) | F30: =SUM(F21:F29) | G30: =SUM(G21:G29) | H30: =SUM(H21:H29) | I30: =SUM(I21:I29) | J30: =SUM(J21:J29) | K30: =SUM(K21:K29) | L30: =SUM(L21:L29) | ... N30: =SUM(N21:N29)
D32: NET OPERATING INCOME | E32: =E18-E30 | F32: =F18-F30 | G32: =G18-G30 | H32: =H18-H30 | I32: =I18-I30 | J32: =J18-J30 | K32: =K18-K30 | L32: =L18-L30 | ... N32: =N18-N30
E33: 0 | F33: 0 | G33: 0 | H33: 0 | I33: 0 | J33: 0 | K33: 0 | L33: 0 | M33: 0 | N33: 0
D34: LEASING & CAPITAL COSTS
D35: Tenant Improvements | E35: =SUMIFS(Proforma!F:F,Proforma!$D:$D,'Annual Cash Flow (3)'!$D35) | F35: =SUMIFS(Proforma!G:G,Proforma!$D:$D,'Annual Cash Flow (3)'!$D35) | G35: =SUMIFS(Proforma!H:H,Proforma!$D:$D,'Annual Cash Flow (3)'!$D35) | H35: =SUMIFS(Proforma!I:I,Proforma!$D:$D,'Annual Cash Flow (3)'!$D35) | I35: =SUMIFS(Proforma!J:J,Proforma!$D:$D,'Annual Cash Flow (3)'!$D35) | J35: =SUMIFS(Proforma!K:K,Proforma!$D:$D,'Annual Cash Flow (3)'!$D35) | K35: =SUMIFS(Proforma!L:L,Proforma!$D:$D,'Annual Cash Flow (3)'!$D35) | L35: =SUMIFS(Proforma!M:M,Proforma!$D:$D,'Annual Cash Flow (3)'!$D35) | M35: =SUMIFS(Proforma!N:N,Proforma!$D:$D,'Annual Cash Flow (3)'!$D35) | N35: =SUMIFS(Proforma!O:O,Proforma!$D:$D,'Annual Cash Flow (3)'!$D35)
D36: Leasing Commissions | E36: =SUMIFS(Proforma!F:F,Proforma!$D:$D,'Annual Cash Flow (3)'!$D36) | F36: =SUMIFS(Proforma!G:G,Proforma!$D:$D,'Annual Cash Flow (3)'!$D36) | G36: =SUMIFS(Proforma!H:H,Proforma!$D:$D,'Annual Cash Flow (3)'!$D36) | H36: =SUMIFS(Proforma!I:I,Proforma!$D:$D,'Annual Cash Flow (3)'!$D36) | I36: =SUMIFS(Proforma!J:J,Proforma!$D:$D,'Annual Cash Flow (3)'!$D36) | J36: =SUMIFS(Proforma!K:K,Proforma!$D:$D,'Annual Cash Flow (3)'!$D36) | K36: =SUMIFS(Proforma!L:L,Proforma!$D:$D,'Annual Cash Flow (3)'!$D36) | L36: =SUMIFS(Proforma!M:M,Proforma!$D:$D,'Annual Cash Flow (3)'!$D36) | M36: =SUMIFS(Proforma!N:N,Proforma!$D:$D,'Annual Cash Flow (3)'!$D36) | N36: =SUMIFS(Proforma!O:O,Proforma!$D:$D,'Annual Cash Flow (3)'!$D36)
D37: Capital Improvements | E37: =SUMIFS(Proforma!F:F,Proforma!$D:$D,'Annual Cash Flow (3)'!$D37) | F37: =SUMIFS(Proforma!G:G,Proforma!$D:$D,'Annual Cash Flow (3)'!$D37) | G37: =SUMIFS(Proforma!H:H,Proforma!$D:$D,'Annual Cash Flow (3)'!$D37) | H37: =SUMIFS(Proforma!I:I,Proforma!$D:$D,'Annual Cash Flow (3)'!$D37) | I37: =SUMIFS(Proforma!J:J,Proforma!$D:$D,'Annual Cash Flow (3)'!$D37) | J37: =SUMIFS(Proforma!K:K,Proforma!$D:$D,'Annual Cash Flow (3)'!$D37) | K37: =SUMIFS(Proforma!L:L,Proforma!$D:$D,'Annual Cash Flow (3)'!$D37) | L37: =SUMIFS(Proforma!M:M,Proforma!$D:$D,'Annual Cash Flow (3)'!$D37) | M37: =SUMIFS(Proforma!N:N,Proforma!$D:$D,'Annual Cash Flow (3)'!$D37) | N37: =SUMIFS(Proforma!O:O,Proforma!$D:$D,'Annual Cash Flow (3)'!$D37)
D38: Structural Reserve / CAPEX | E38: =SUMIFS(Proforma!F:F,Proforma!$D:$D,'Annual Cash Flow (3)'!$D38) | F38: =SUMIFS(Proforma!G:G,Proforma!$D:$D,'Annual Cash Flow (3)'!$D38) | G38: =SUMIFS(Proforma!H:H,Proforma!$D:$D,'Annual Cash Flow (3)'!$D38) | H38: =SUMIFS(Proforma!I:I,Proforma!$D:$D,'Annual Cash Flow (3)'!$D38) | I38: =SUMIFS(Proforma!J:J,Proforma!$D:$D,'Annual Cash Flow (3)'!$D38) | J38: =SUMIFS(Proforma!K:K,Proforma!$D:$D,'Annual Cash Flow (3)'!$D38) | K38: =SUMIFS(Proforma!L:L,Proforma!$D:$D,'Annual Cash Flow (3)'!$D38) | L38: =SUMIFS(Proforma!M:M,Proforma!$D:$D,'Annual Cash Flow (3)'!$D38) | M38: =SUMIFS(Proforma!N:N,Proforma!$D:$D,'Annual Cash Flow (3)'!$D38) | N38: =SUMIFS(Proforma!O:O,Proforma!$D:$D,'Annual Cash Flow (3)'!$D38)
D39: TOTAL LEASING & CAPITAL COSTS | E39: =SUM(E35:E38) | F39: =SUM(F35:F38) | G39: =SUM(G35:G38) | H39: =SUM(H35:H38) | I39: =SUM(I35:I38) | J39: =SUM(J35:J38) | K39: =SUM(K35:K38) | L39: =SUM(L35:L38) | ... N39: =SUM(N35:N38)
D41: UNLEVERAGED CASH FLOW | E41: =E32-E39 | F41: =F32-F39 | G41: =G32-G39 | H41: =H32-H39 | I41: =I32-I39 | J41: =J32-J39 | K41: =K32-K39 | L41: =L32-L39 | ... N41: =N32-N39
